Traceback (most recent call last):
  File "speech_recognition\__init__.py", line 108, in get_pyaudio
ModuleNotFoundError: No module named 'pyaudio'

During handling of the above exception, another exception occurred:

Traceback (most recent call last):
  File "simple.py", line 16, in get_mic
    try:
  File "speech_recognition\__init__.py", line 79, in __init__
  File "speech_recognition\__init__.py", line 110, in get_pyaudio
AttributeError: Could not find PyAudio; check installation

During handling of the above exception, another exception occurred:

Traceback (most recent call last):
  File "speech_recognition\__init__.py", line 108, in get_pyaudio
ModuleNotFoundError: No module named 'pyaudio'

During handling of the above exception, another exception occurred:

Traceback (most recent call last):
  File "simple.py", line 21, in get_mic
    try:
  File "speech_recognition\__init__.py", line 79, in __init__
  File "speech_recognition\__init__.py", line 110, in get_pyaudio
AttributeError: Could not find PyAudio; check installation
